[2024-07-16T04:38:37.972+0000] {local_task_job_runner.py:120} INFO - ::group::Pre task execution logs
[2024-07-16T04:38:37.986+0000] {taskinstance.py:2076} INFO - Dependencies all met for dep_context=non-requeueable deps ti=<TaskInstance: consumer.read_dataset manual__2024-07-16T04:38:35.958470+00:00 [queued]>
[2024-07-16T04:38:37.989+0000] {taskinstance.py:2076} INFO - Dependencies all met for dep_context=requeueable deps ti=<TaskInstance: consumer.read_dataset manual__2024-07-16T04:38:35.958470+00:00 [queued]>
[2024-07-16T04:38:37.990+0000] {taskinstance.py:2306} INFO - Starting attempt 1 of 1
[2024-07-16T04:38:38.001+0000] {taskinstance.py:2330} INFO - Executing <Task(_PythonDecoratedOperator): read_dataset> on 2024-07-16 04:38:35.958470+00:00
[2024-07-16T04:38:38.007+0000] {warnings.py:112} WARNING - /home/***/.local/lib/python3.12/site-packages/***/task/task_runner/standard_task_runner.py:61: DeprecationWarning: This process (pid=197) is multi-threaded, use of fork() may lead to deadlocks in the child.
  pid = os.fork()

[2024-07-16T04:38:38.007+0000] {standard_task_runner.py:63} INFO - Started process 199 to run task
[2024-07-16T04:38:38.008+0000] {standard_task_runner.py:90} INFO - Running: ['***', 'tasks', 'run', 'consumer', 'read_dataset', 'manual__2024-07-16T04:38:35.958470+00:00', '--job-id', '51', '--raw', '--subdir', 'DAGS_FOLDER/consumer.py', '--cfg-path', '/tmp/tmp_3wd58f_']
[2024-07-16T04:38:38.009+0000] {standard_task_runner.py:91} INFO - Job 51: Subtask read_dataset
[2024-07-16T04:38:38.044+0000] {task_command.py:426} INFO - Running <TaskInstance: consumer.read_dataset manual__2024-07-16T04:38:35.958470+00:00 [running]> on host 6e5e891f9a78
[2024-07-16T04:38:38.093+0000] {taskinstance.py:2648} INFO - Exporting env vars: AIRFLOW_CTX_DAG_OWNER='***' AIRFLOW_CTX_DAG_ID='consumer' AIRFLOW_CTX_TASK_ID='read_dataset' AIRFLOW_CTX_EXECUTION_DATE='2024-07-16T04:38:35.958470+00:00' AIRFLOW_CTX_TRY_NUMBER='1' AIRFLOW_CTX_DAG_RUN_ID='manual__2024-07-16T04:38:35.958470+00:00'
[2024-07-16T04:38:38.094+0000] {taskinstance.py:430} INFO - ::endgroup::
[2024-07-16T04:38:38.094+0000] {taskinstance.py:441} INFO - ::group::Post task execution logs
[2024-07-16T04:38:38.095+0000] {taskinstance.py:2905} ERROR - Task failed with exception
Traceback (most recent call last):
  File "/home/airflow/.local/lib/python3.12/site-packages/airflow/models/taskinstance.py", line 465, in _execute_task
    result = _execute_callable(context=context, **execute_callable_kwargs)
             ^^^^^^^^^^^^^^^^^^^^^^^^^^^^^^^^^^^^^^^^^^^^^^^^^^^^^^^^^^^^^
  File "/home/airflow/.local/lib/python3.12/site-packages/airflow/models/taskinstance.py", line 432, in _execute_callable
    return execute_callable(context=context, **execute_callable_kwargs)
           ^^^^^^^^^^^^^^^^^^^^^^^^^^^^^^^^^^^^^^^^^^^^^^^^^^^^^^^^^^^^
  File "/home/airflow/.local/lib/python3.12/site-packages/airflow/models/baseoperator.py", line 401, in wrapper
    return func(self, *args, **kwargs)
           ^^^^^^^^^^^^^^^^^^^^^^^^^^^
  File "/home/airflow/.local/lib/python3.12/site-packages/airflow/decorators/base.py", line 265, in execute
    return_value = super().execute(context)
                   ^^^^^^^^^^^^^^^^^^^^^^^^
  File "/home/airflow/.local/lib/python3.12/site-packages/airflow/models/baseoperator.py", line 401, in wrapper
    return func(self, *args, **kwargs)
           ^^^^^^^^^^^^^^^^^^^^^^^^^^^
  File "/home/airflow/.local/lib/python3.12/site-packages/airflow/operators/python.py", line 235, in execute
    return_value = self.execute_callable()
                   ^^^^^^^^^^^^^^^^^^^^^^^
  File "/home/airflow/.local/lib/python3.12/site-packages/airflow/operators/python.py", line 252, in execute_callable
    return self.python_callable(*self.op_args, **self.op_kwargs)
           ^^^^^^^^^^^^^^^^^^^^^^^^^^^^^^^^^^^^^^^^^^^^^^^^^^^^^
  File "/opt/airflow/dags/consumer.py", line 17, in read_dataset
    with open(my_file.uri,"r") as f:
         ^^^^^^^^^^^^^^^^^^^^^
FileNotFoundError: [Errno 2] No such file or directory: '/tmp/my_file.txt'
[2024-07-16T04:38:38.107+0000] {taskinstance.py:1206} INFO - Marking task as FAILED. dag_id=consumer, task_id=read_dataset, run_id=manual__2024-07-16T04:38:35.958470+00:00, execution_date=20240716T043835, start_date=20240716T043837, end_date=20240716T043838
[2024-07-16T04:38:38.114+0000] {standard_task_runner.py:110} ERROR - Failed to execute job 51 for task read_dataset ([Errno 2] No such file or directory: '/tmp/my_file.txt'; 199)
[2024-07-16T04:38:38.144+0000] {local_task_job_runner.py:240} INFO - Task exited with return code 1
[2024-07-16T04:38:38.152+0000] {taskinstance.py:3503} INFO - 0 downstream tasks scheduled from follow-on schedule check
[2024-07-16T04:38:38.153+0000] {local_task_job_runner.py:222} INFO - ::endgroup::
